2020-06-11 15:49:36,153,5776,django.request,ERROR,log.py:228,Internal Server Error: /api/v1/interface_set/update_interface/1/
Traceback (most recent call last):
  File "/Users/zhuzhanhao/opt/anaconda3/envs/py37/lib/python3.7/site-packages/django/core/handlers/exception.py", line 34, in inner
    response = get_response(request)
  File "/Users/zhuzhanhao/opt/anaconda3/envs/py37/lib/python3.7/site-packages/django/core/handlers/base.py", line 115, in _get_response
    response = self.process_exception_by_middleware(e, request)
  File "/Users/zhuzhanhao/opt/anaconda3/envs/py37/lib/python3.7/site-packages/django/core/handlers/base.py", line 113, in _get_response
    response = wrapped_callback(request, *callback_args, **callback_kwargs)
  File "/Users/zhuzhanhao/opt/anaconda3/envs/py37/lib/python3.7/site-packages/django/views/decorators/csrf.py", line 54, in wrapped_view
    return view_func(*args, **kwargs)
  File "/Users/zhuzhanhao/opt/anaconda3/envs/py37/lib/python3.7/site-packages/django/views/generic/base.py", line 71, in view
    return self.dispatch(request, *args, **kwargs)
  File "/Users/zhuzhanhao/opt/anaconda3/envs/py37/lib/python3.7/site-packages/rest_framework/views.py", line 507, in dispatch
    self.response = self.finalize_response(request, response, *args, **kwargs)
  File "/Users/zhuzhanhao/opt/anaconda3/envs/py37/lib/python3.7/site-packages/rest_framework/views.py", line 422, in finalize_response
    % type(response)
AssertionError: Expected a `Response`, `HttpResponse` or `HttpStreamingResponse` to be returned from the view, but received a `<class 'NoneType'>`
2020-06-11 15:49:36,156,5776,django.server,ERROR,basehttp.py:157,"PUT /api/v1/interface_set/update_interface/1/ HTTP/1.1" 500 16164
