2020-06-11 15:49:36,153,5776,django.request,ERROR,log.py:228,Internal Server Error: /api/v1/interface_set/update_interface/1/
Traceback (most recent call last):
  File "/Users/zhuzhanhao/opt/anaconda3/envs/py37/lib/python3.7/site-packages/django/core/handlers/exception.py", line 34, in inner
    response = get_response(request)
  File "/Users/zhuzhanhao/opt/anaconda3/envs/py37/lib/python3.7/site-packages/django/core/handlers/base.py", line 115, in _get_response
    response = self.process_exception_by_middleware(e, request)
  File "/Users/zhuzhanhao/opt/anaconda3/envs/py37/lib/python3.7/site-packages/django/core/handlers/base.py", line 113, in _get_response
    response = wrapped_callback(request, *callback_args, **callback_kwargs)
  File "/Users/zhuzhanhao/opt/anaconda3/envs/py37/lib/python3.7/site-packages/django/views/decorators/csrf.py", line 54, in wrapped_view
    return view_func(*args, **kwargs)
  File "/Users/zhuzhanhao/opt/anaconda3/envs/py37/lib/python3.7/site-packages/django/views/generic/base.py", line 71, in view
    return self.dispatch(request, *args, **kwargs)
  File "/Users/zhuzhanhao/opt/anaconda3/envs/py37/lib/python3.7/site-packages/rest_framework/views.py", line 507, in dispatch
    self.response = self.finalize_response(request, response, *args, **kwargs)
  File "/Users/zhuzhanhao/opt/anaconda3/envs/py37/lib/python3.7/site-packages/rest_framework/views.py", line 422, in finalize_response
    % type(response)
AssertionError: Expected a `Response`, `HttpResponse` or `HttpStreamingResponse` to be returned from the view, but received a `<class 'NoneType'>`
2020-06-11 15:49:36,156,5776,django.server,ERROR,basehttp.py:157,"PUT /api/v1/interface_set/update_interface/1/ HTTP/1.1" 500 16164
2020-06-11 20:41:36,412,6380,django.request,ERROR,log.py:228,Internal Server Error: /api/v1/interface_set/debug_test/
Traceback (most recent call last):
  File "D:\Anaconda3\envs\test\lib\site-packages\urllib3\connection.py", line 157, in _new_conn
    (self._dns_host, self.port), self.timeout, **extra_kw
  File "D:\Anaconda3\envs\test\lib\site-packages\urllib3\util\connection.py", line 84, in create_connection
    raise err
  File "D:\Anaconda3\envs\test\lib\site-packages\urllib3\util\connection.py", line 74, in create_connection
    sock.connect(sa)
TimeoutError: [WinError 10060] 由于连接方在一段时间后没有正确答复或连接的主机没有反应，连接尝试失败。

During handling of the above exception, another exception occurred:

Traceback (most recent call last):
  File "D:\Anaconda3\envs\test\lib\site-packages\urllib3\connectionpool.py", line 672, in urlopen
    chunked=chunked,
  File "D:\Anaconda3\envs\test\lib\site-packages\urllib3\connectionpool.py", line 387, in _make_request
    conn.request(method, url, **httplib_request_kw)
  File "D:\Anaconda3\envs\test\lib\http\client.py", line 1252, in request
    self._send_request(method, url, body, headers, encode_chunked)
  File "D:\Anaconda3\envs\test\lib\http\client.py", line 1298, in _send_request
    self.endheaders(body, encode_chunked=encode_chunked)
  File "D:\Anaconda3\envs\test\lib\http\client.py", line 1247, in endheaders
    self._send_output(message_body, encode_chunked=encode_chunked)
  File "D:\Anaconda3\envs\test\lib\http\client.py", line 1026, in _send_output
    self.send(msg)
  File "D:\Anaconda3\envs\test\lib\http\client.py", line 966, in send
    self.connect()
  File "D:\Anaconda3\envs\test\lib\site-packages\urllib3\connection.py", line 184, in connect
    conn = self._new_conn()
  File "D:\Anaconda3\envs\test\lib\site-packages\urllib3\connection.py", line 169, in _new_conn
    self, "Failed to establish a new connection: %s" % e
urllib3.exceptions.NewConnectionError: <urllib3.connection.HTTPConnection object at 0x0000016BDEA19508>: Failed to establish a new connection: [WinError 10060] 由于连接方在一段时间后没有正确答复或连接的主机没有反应，连接尝试失败。

During handling of the above exception, another exception occurred:

Traceback (most recent call last):
  File "D:\Anaconda3\envs\test\lib\site-packages\requests\adapters.py", line 449, in send
    timeout=timeout
  File "D:\Anaconda3\envs\test\lib\site-packages\urllib3\connectionpool.py", line 720, in urlopen
    method, url, error=e, _pool=self, _stacktrace=sys.exc_info()[2]
  File "D:\Anaconda3\envs\test\lib\site-packages\urllib3\util\retry.py", line 436, in increment
    raise MaxRetryError(_pool, url, error or ResponseError(cause))
urllib3.exceptions.MaxRetryError: HTTPConnectionPool(host='192.168.10.78', port=80): Max retries exceeded with url: /ermsapi/policy/get_retention_policy_list (Caused by NewConnectionError('<urllib3.connection.HTTPConnection object at 0x0000016BDEA19508>: Failed to establish a new connection: [WinError 10060] 由于连接方在一段时间后没有正确答复或连接的主机没有反应，连接尝试失败。'))

During handling of the above exception, another exception occurred:

Traceback (most recent call last):
  File "D:\Anaconda3\envs\test\lib\site-packages\django\core\handlers\exception.py", line 34, in inner
    response = get_response(request)
  File "D:\Anaconda3\envs\test\lib\site-packages\django\core\handlers\base.py", line 115, in _get_response
    response = self.process_exception_by_middleware(e, request)
  File "D:\Anaconda3\envs\test\lib\site-packages\django\core\handlers\base.py", line 113, in _get_response
    response = wrapped_callback(request, *callback_args, **callback_kwargs)
  File "D:\Anaconda3\envs\test\lib\site-packages\django\views\decorators\csrf.py", line 54, in wrapped_view
    return view_func(*args, **kwargs)
  File "D:\Anaconda3\envs\test\lib\site-packages\django\views\generic\base.py", line 71, in view
    return self.dispatch(request, *args, **kwargs)
  File "D:\Anaconda3\envs\test\lib\site-packages\rest_framework\views.py", line 505, in dispatch
    response = self.handle_exception(exc)
  File "D:\Anaconda3\envs\test\lib\site-packages\rest_framework\views.py", line 465, in handle_exception
    self.raise_uncaught_exception(exc)
  File "D:\Anaconda3\envs\test\lib\site-packages\rest_framework\views.py", line 476, in raise_uncaught_exception
    raise exc
  File "D:\Anaconda3\envs\test\lib\site-packages\rest_framework\views.py", line 502, in dispatch
    response = handler(request, *args, **kwargs)
  File "D:\python\project\Easytest\easy\api\interFace\interFace.py", line 275, in post
    params, body)
  File "D:\python\project\Easytest\easy\common\interfaceRun.py", line 69, in run_main
    res = self.get(url,headers,params)
  File "D:\python\project\Easytest\easy\common\interfaceRun.py", line 11, in get
    res = requests.get(url, params=params, headers=headers)
  File "D:\Anaconda3\envs\test\lib\site-packages\requests\api.py", line 76, in get
    return request('get', url, params=params, **kwargs)
  File "D:\Anaconda3\envs\test\lib\site-packages\requests\api.py", line 61, in request
    return session.request(method=method, url=url, **kwargs)
  File "D:\Anaconda3\envs\test\lib\site-packages\requests\sessions.py", line 530, in request
    resp = self.send(prep, **send_kwargs)
  File "D:\Anaconda3\envs\test\lib\site-packages\requests\sessions.py", line 643, in send
    r = adapter.send(request, **kwargs)
  File "D:\Anaconda3\envs\test\lib\site-packages\requests\adapters.py", line 516, in send
    raise ConnectionError(e, request=request)
requests.exceptions.ConnectionError: HTTPConnectionPool(host='192.168.10.78', port=80): Max retries exceeded with url: /ermsapi/policy/get_retention_policy_list (Caused by NewConnectionError('<urllib3.connection.HTTPConnection object at 0x0000016BDEA19508>: Failed to establish a new connection: [WinError 10060] 由于连接方在一段时间后没有正确答复或连接的主机没有反应，连接尝试失败。'))
2020-06-11 20:41:36,418,6380,django.server,ERROR,basehttp.py:157,"POST /api/v1/interface_set/debug_test/ HTTP/1.1" 500 21823
2020-06-11 22:15:56,452,2180,django.request,ERROR,log.py:228,Internal Server Error: /api/v1/interface_set/test/
Traceback (most recent call last):
  File "D:\Anaconda3\envs\test\lib\site-packages\django\core\handlers\exception.py", line 34, in inner
    response = get_response(request)
  File "D:\Anaconda3\envs\test\lib\site-packages\django\core\handlers\base.py", line 115, in _get_response
    response = self.process_exception_by_middleware(e, request)
  File "D:\Anaconda3\envs\test\lib\site-packages\django\core\handlers\base.py", line 113, in _get_response
    response = wrapped_callback(request, *callback_args, **callback_kwargs)
  File "D:\Anaconda3\envs\test\lib\site-packages\django\views\decorators\csrf.py", line 54, in wrapped_view
    return view_func(*args, **kwargs)
  File "D:\Anaconda3\envs\test\lib\site-packages\django\views\generic\base.py", line 71, in view
    return self.dispatch(request, *args, **kwargs)
  File "D:\Anaconda3\envs\test\lib\site-packages\rest_framework\views.py", line 505, in dispatch
    response = self.handle_exception(exc)
  File "D:\Anaconda3\envs\test\lib\site-packages\rest_framework\views.py", line 465, in handle_exception
    self.raise_uncaught_exception(exc)
  File "D:\Anaconda3\envs\test\lib\site-packages\rest_framework\views.py", line 476, in raise_uncaught_exception
    raise exc
  File "D:\Anaconda3\envs\test\lib\site-packages\rest_framework\views.py", line 502, in dispatch
    response = handler(request, *args, **kwargs)
  File "D:\python\project\Easytest\easy\api\interFace\interFace.py", line 291, in get
    obj = InterFaceSet.objects.filter(id_in = [1,2,3]).values("interface_name")
  File "D:\Anaconda3\envs\test\lib\site-packages\django\db\models\manager.py", line 82, in manager_method
    return getattr(self.get_queryset(), name)(*args, **kwargs)
  File "D:\Anaconda3\envs\test\lib\site-packages\django\db\models\query.py", line 904, in filter
    return self._filter_or_exclude(False, *args, **kwargs)
  File "D:\Anaconda3\envs\test\lib\site-packages\django\db\models\query.py", line 923, in _filter_or_exclude
    clone.query.add_q(Q(*args, **kwargs))
  File "D:\Anaconda3\envs\test\lib\site-packages\django\db\models\sql\query.py", line 1350, in add_q
    clause, _ = self._add_q(q_object, self.used_aliases)
  File "D:\Anaconda3\envs\test\lib\site-packages\django\db\models\sql\query.py", line 1381, in _add_q
    check_filterable=check_filterable,
  File "D:\Anaconda3\envs\test\lib\site-packages\django\db\models\sql\query.py", line 1250, in build_filter
    lookups, parts, reffed_expression = self.solve_lookup_type(arg)
  File "D:\Anaconda3\envs\test\lib\site-packages\django\db\models\sql\query.py", line 1087, in solve_lookup_type
    _, field, _, lookup_parts = self.names_to_path(lookup_splitted, self.get_meta())
  File "D:\Anaconda3\envs\test\lib\site-packages\django\db\models\sql\query.py", line 1483, in names_to_path
    "Choices are: %s" % (name, ", ".join(available)))
django.core.exceptions.FieldError: Cannot resolve keyword 'id_in' into field. Choices are: belong_module, belong_module_id, body, depend_id, depend_key, duration, exceptres, head, header, id, identity, interface_name, method, params, preprocessor, replace_key, replace_position, result, sortid, url
2020-06-11 22:15:56,454,2180,django.server,ERROR,basehttp.py:157,"GET /api/v1/interface_set/test/ HTTP/1.1" 500 18520
2020-06-11 22:19:02,755,1592,django.request,ERROR,log.py:228,Internal Server Error: /api/v1/interface_set/test/
Traceback (most recent call last):
  File "D:\Anaconda3\envs\test\lib\site-packages\django\core\handlers\exception.py", line 34, in inner
    response = get_response(request)
  File "D:\Anaconda3\envs\test\lib\site-packages\django\core\handlers\base.py", line 115, in _get_response
    response = self.process_exception_by_middleware(e, request)
  File "D:\Anaconda3\envs\test\lib\site-packages\django\core\handlers\base.py", line 113, in _get_response
    response = wrapped_callback(request, *callback_args, **callback_kwargs)
  File "D:\Anaconda3\envs\test\lib\site-packages\django\views\decorators\csrf.py", line 54, in wrapped_view
    return view_func(*args, **kwargs)
  File "D:\Anaconda3\envs\test\lib\site-packages\django\views\generic\base.py", line 71, in view
    return self.dispatch(request, *args, **kwargs)
  File "D:\Anaconda3\envs\test\lib\site-packages\rest_framework\views.py", line 505, in dispatch
    response = self.handle_exception(exc)
  File "D:\Anaconda3\envs\test\lib\site-packages\rest_framework\views.py", line 465, in handle_exception
    self.raise_uncaught_exception(exc)
  File "D:\Anaconda3\envs\test\lib\site-packages\rest_framework\views.py", line 476, in raise_uncaught_exception
    raise exc
  File "D:\Anaconda3\envs\test\lib\site-packages\rest_framework\views.py", line 502, in dispatch
    response = handler(request, *args, **kwargs)
  File "D:\python\project\Easytest\easy\api\interFace\interFace.py", line 291, in get
    obj = InterFaceSet.objects.filter(pk_in = [1,2,3]).values("interface_name")
  File "D:\Anaconda3\envs\test\lib\site-packages\django\db\models\manager.py", line 82, in manager_method
    return getattr(self.get_queryset(), name)(*args, **kwargs)
  File "D:\Anaconda3\envs\test\lib\site-packages\django\db\models\query.py", line 904, in filter
    return self._filter_or_exclude(False, *args, **kwargs)
  File "D:\Anaconda3\envs\test\lib\site-packages\django\db\models\query.py", line 923, in _filter_or_exclude
    clone.query.add_q(Q(*args, **kwargs))
  File "D:\Anaconda3\envs\test\lib\site-packages\django\db\models\sql\query.py", line 1350, in add_q
    clause, _ = self._add_q(q_object, self.used_aliases)
  File "D:\Anaconda3\envs\test\lib\site-packages\django\db\models\sql\query.py", line 1381, in _add_q
    check_filterable=check_filterable,
  File "D:\Anaconda3\envs\test\lib\site-packages\django\db\models\sql\query.py", line 1250, in build_filter
    lookups, parts, reffed_expression = self.solve_lookup_type(arg)
  File "D:\Anaconda3\envs\test\lib\site-packages\django\db\models\sql\query.py", line 1087, in solve_lookup_type
    _, field, _, lookup_parts = self.names_to_path(lookup_splitted, self.get_meta())
  File "D:\Anaconda3\envs\test\lib\site-packages\django\db\models\sql\query.py", line 1483, in names_to_path
    "Choices are: %s" % (name, ", ".join(available)))
django.core.exceptions.FieldError: Cannot resolve keyword 'pk_in' into field. Choices are: belong_module, belong_module_id, body, depend_id, depend_key, duration, exceptres, head, header, id, identity, interface_name, method, params, preprocessor, replace_key, replace_position, result, sortid, url
2020-06-11 22:19:02,759,1592,django.server,ERROR,basehttp.py:157,"GET /api/v1/interface_set/test/ HTTP/1.1" 500 18520
2020-06-11 22:22:30,843,10288,django.request,ERROR,log.py:228,Internal Server Error: /api/v1/interface_set/test/
Traceback (most recent call last):
  File "D:\Anaconda3\envs\test\lib\site-packages\django\core\handlers\exception.py", line 34, in inner
    response = get_response(request)
  File "D:\Anaconda3\envs\test\lib\site-packages\django\core\handlers\base.py", line 115, in _get_response
    response = self.process_exception_by_middleware(e, request)
  File "D:\Anaconda3\envs\test\lib\site-packages\django\core\handlers\base.py", line 113, in _get_response
    response = wrapped_callback(request, *callback_args, **callback_kwargs)
  File "D:\Anaconda3\envs\test\lib\site-packages\django\views\decorators\csrf.py", line 54, in wrapped_view
    return view_func(*args, **kwargs)
  File "D:\Anaconda3\envs\test\lib\site-packages\django\views\generic\base.py", line 71, in view
    return self.dispatch(request, *args, **kwargs)
  File "D:\Anaconda3\envs\test\lib\site-packages\rest_framework\views.py", line 505, in dispatch
    response = self.handle_exception(exc)
  File "D:\Anaconda3\envs\test\lib\site-packages\rest_framework\views.py", line 465, in handle_exception
    self.raise_uncaught_exception(exc)
  File "D:\Anaconda3\envs\test\lib\site-packages\rest_framework\views.py", line 476, in raise_uncaught_exception
    raise exc
  File "D:\Anaconda3\envs\test\lib\site-packages\rest_framework\views.py", line 502, in dispatch
    response = handler(request, *args, **kwargs)
  File "D:\python\project\Easytest\easy\api\interFace\interFace.py", line 291, in get
    obj = InterFaceSet.objects.filter(id([1,2,3])).values("interface_name")
  File "D:\Anaconda3\envs\test\lib\site-packages\django\db\models\manager.py", line 82, in manager_method
    return getattr(self.get_queryset(), name)(*args, **kwargs)
  File "D:\Anaconda3\envs\test\lib\site-packages\django\db\models\query.py", line 904, in filter
    return self._filter_or_exclude(False, *args, **kwargs)
  File "D:\Anaconda3\envs\test\lib\site-packages\django\db\models\query.py", line 923, in _filter_or_exclude
    clone.query.add_q(Q(*args, **kwargs))
  File "D:\Anaconda3\envs\test\lib\site-packages\django\db\models\sql\query.py", line 1350, in add_q
    clause, _ = self._add_q(q_object, self.used_aliases)
  File "D:\Anaconda3\envs\test\lib\site-packages\django\db\models\sql\query.py", line 1381, in _add_q
    check_filterable=check_filterable,
  File "D:\Anaconda3\envs\test\lib\site-packages\django\db\models\sql\query.py", line 1247, in build_filter
    arg, value = filter_expr
TypeError: cannot unpack non-iterable int object
2020-06-11 22:22:30,845,10288,django.server,ERROR,basehttp.py:157,"GET /api/v1/interface_set/test/ HTTP/1.1" 500 17662
2020-06-11 22:26:52,988,1728,django.request,ERROR,log.py:228,Internal Server Error: /api/v1/interface_set/test/
Traceback (most recent call last):
  File "D:\Anaconda3\envs\test\lib\site-packages\django\core\handlers\exception.py", line 34, in inner
    response = get_response(request)
  File "D:\Anaconda3\envs\test\lib\site-packages\django\core\handlers\base.py", line 115, in _get_response
    response = self.process_exception_by_middleware(e, request)
  File "D:\Anaconda3\envs\test\lib\site-packages\django\core\handlers\base.py", line 113, in _get_response
    response = wrapped_callback(request, *callback_args, **callback_kwargs)
  File "D:\Anaconda3\envs\test\lib\site-packages\django\views\decorators\csrf.py", line 54, in wrapped_view
    return view_func(*args, **kwargs)
  File "D:\Anaconda3\envs\test\lib\site-packages\django\views\generic\base.py", line 71, in view
    return self.dispatch(request, *args, **kwargs)
  File "D:\Anaconda3\envs\test\lib\site-packages\rest_framework\views.py", line 505, in dispatch
    response = self.handle_exception(exc)
  File "D:\Anaconda3\envs\test\lib\site-packages\rest_framework\views.py", line 465, in handle_exception
    self.raise_uncaught_exception(exc)
  File "D:\Anaconda3\envs\test\lib\site-packages\rest_framework\views.py", line 476, in raise_uncaught_exception
    raise exc
  File "D:\Anaconda3\envs\test\lib\site-packages\rest_framework\views.py", line 502, in dispatch
    response = handler(request, *args, **kwargs)
  File "D:\python\project\Easytest\easy\api\interFace\interFace.py", line 292, in get
    "params","body","depend_id","depend_key","replace_key","replace_position",flat=True)
  File "D:\Anaconda3\envs\test\lib\site-packages\django\db\models\query.py", line 817, in values_list
    raise TypeError("'flat' is not valid when values_list is called with more than one field.")
TypeError: 'flat' is not valid when values_list is called with more than one field.
2020-06-11 22:26:52,990,1728,django.server,ERROR,basehttp.py:157,"GET /api/v1/interface_set/test/ HTTP/1.1" 500 17031
2020-06-11 22:27:07,263,8312,django.request,ERROR,log.py:228,Internal Server Error: /api/v1/interface_set/test/
Traceback (most recent call last):
  File "D:\Anaconda3\envs\test\lib\site-packages\django\db\models\sql\query.py", line 1865, in add_fields
    join_info = self.setup_joins(name.split(LOOKUP_SEP), opts, alias, allow_many=allow_m2m)
  File "D:\Anaconda3\envs\test\lib\site-packages\django\db\models\sql\query.py", line 1567, in setup_joins
    names[:pivot], opts, allow_many, fail_on_missing=True,
  File "D:\Anaconda3\envs\test\lib\site-packages\django\db\models\sql\query.py", line 1483, in names_to_path
    "Choices are: %s" % (name, ", ".join(available)))
django.core.exceptions.FieldError: Cannot resolve keyword 'headers' into field. Choices are: belong_module, belong_module_id, body, depend_id, depend_key, duration, exceptres, head, header, id, identity, interface_name, method, params, preprocessor, replace_key, replace_position, result, sortid, url

During handling of the above exception, another exception occurred:

Traceback (most recent call last):
  File "D:\Anaconda3\envs\test\lib\site-packages\django\core\handlers\exception.py", line 34, in inner
    response = get_response(request)
  File "D:\Anaconda3\envs\test\lib\site-packages\django\core\handlers\base.py", line 115, in _get_response
    response = self.process_exception_by_middleware(e, request)
  File "D:\Anaconda3\envs\test\lib\site-packages\django\core\handlers\base.py", line 113, in _get_response
    response = wrapped_callback(request, *callback_args, **callback_kwargs)
  File "D:\Anaconda3\envs\test\lib\site-packages\django\views\decorators\csrf.py", line 54, in wrapped_view
    return view_func(*args, **kwargs)
  File "D:\Anaconda3\envs\test\lib\site-packages\django\views\generic\base.py", line 71, in view
    return self.dispatch(request, *args, **kwargs)
  File "D:\Anaconda3\envs\test\lib\site-packages\rest_framework\views.py", line 505, in dispatch
    response = self.handle_exception(exc)
  File "D:\Anaconda3\envs\test\lib\site-packages\rest_framework\views.py", line 465, in handle_exception
    self.raise_uncaught_exception(exc)
  File "D:\Anaconda3\envs\test\lib\site-packages\rest_framework\views.py", line 476, in raise_uncaught_exception
    raise exc
  File "D:\Anaconda3\envs\test\lib\site-packages\rest_framework\views.py", line 502, in dispatch
    response = handler(request, *args, **kwargs)
  File "D:\python\project\Easytest\easy\api\interFace\interFace.py", line 292, in get
    "params","body","depend_id","depend_key","replace_key","replace_position")
  File "D:\Anaconda3\envs\test\lib\site-packages\django\db\models\query.py", line 836, in values_list
    clone = self._values(*_fields, **expressions)
  File "D:\Anaconda3\envs\test\lib\site-packages\django\db\models\query.py", line 804, in _values
    clone.query.set_values(fields)
  File "D:\Anaconda3\envs\test\lib\site-packages\django\db\models\sql\query.py", line 2145, in set_values
    self.add_fields(field_names, True)
  File "D:\Anaconda3\envs\test\lib\site-packages\django\db\models\sql\query.py", line 1888, in add_fields
    "Choices are: %s" % (name, ", ".join(names)))
django.core.exceptions.FieldError: Cannot resolve keyword 'headers' into field. Choices are: belong_module, belong_module_id, body, depend_id, depend_key, duration, exceptres, head, header, id, identity, interface_name, method, params, preprocessor, replace_key, replace_position, result, sortid, url
2020-06-11 22:27:07,268,8312,django.server,ERROR,basehttp.py:157,"GET /api/v1/interface_set/test/ HTTP/1.1" 500 18661
2020-06-11 22:32:08,107,7108,django.request,ERROR,log.py:228,Internal Server Error: /api/v1/interface_set/test/
Traceback (most recent call last):
  File "D:\Anaconda3\envs\test\lib\site-packages\django\core\handlers\exception.py", line 34, in inner
    response = get_response(request)
  File "D:\Anaconda3\envs\test\lib\site-packages\django\core\handlers\base.py", line 115, in _get_response
    response = self.process_exception_by_middleware(e, request)
  File "D:\Anaconda3\envs\test\lib\site-packages\django\core\handlers\base.py", line 113, in _get_response
    response = wrapped_callback(request, *callback_args, **callback_kwargs)
  File "D:\Anaconda3\envs\test\lib\site-packages\django\views\decorators\csrf.py", line 54, in wrapped_view
    return view_func(*args, **kwargs)
  File "D:\Anaconda3\envs\test\lib\site-packages\django\views\generic\base.py", line 71, in view
    return self.dispatch(request, *args, **kwargs)
  File "D:\Anaconda3\envs\test\lib\site-packages\rest_framework\views.py", line 505, in dispatch
    response = self.handle_exception(exc)
  File "D:\Anaconda3\envs\test\lib\site-packages\rest_framework\views.py", line 465, in handle_exception
    self.raise_uncaught_exception(exc)
  File "D:\Anaconda3\envs\test\lib\site-packages\rest_framework\views.py", line 476, in raise_uncaught_exception
    raise exc
  File "D:\Anaconda3\envs\test\lib\site-packages\rest_framework\views.py", line 502, in dispatch
    response = handler(request, *args, **kwargs)
  File "D:\python\project\Easytest\easy\api\interFace\interFace.py", line 293, in get
    print(obj[0][0])
KeyError: 0
2020-06-11 22:32:08,110,7108,django.server,ERROR,basehttp.py:157,"GET /api/v1/interface_set/test/ HTTP/1.1" 500 16621
2020-06-12 15:47:29,187,23671,django.request,ERROR,log.py:228,Internal Server Error: /api/v1/interface_manager/menu/
Traceback (most recent call last):
  File "/Users/zhuzhanhao/opt/anaconda3/envs/py37/lib/python3.7/site-packages/django/core/handlers/exception.py", line 34, in inner
    response = get_response(request)
  File "/Users/zhuzhanhao/opt/anaconda3/envs/py37/lib/python3.7/site-packages/django/core/handlers/base.py", line 115, in _get_response
    response = self.process_exception_by_middleware(e, request)
  File "/Users/zhuzhanhao/opt/anaconda3/envs/py37/lib/python3.7/site-packages/django/core/handlers/base.py", line 113, in _get_response
    response = wrapped_callback(request, *callback_args, **callback_kwargs)
  File "/Users/zhuzhanhao/opt/anaconda3/envs/py37/lib/python3.7/site-packages/django/views/decorators/csrf.py", line 54, in wrapped_view
    return view_func(*args, **kwargs)
  File "/Users/zhuzhanhao/opt/anaconda3/envs/py37/lib/python3.7/site-packages/django/views/generic/base.py", line 71, in view
    return self.dispatch(request, *args, **kwargs)
  File "/Users/zhuzhanhao/opt/anaconda3/envs/py37/lib/python3.7/site-packages/rest_framework/views.py", line 505, in dispatch
    response = self.handle_exception(exc)
  File "/Users/zhuzhanhao/opt/anaconda3/envs/py37/lib/python3.7/site-packages/rest_framework/views.py", line 465, in handle_exception
    self.raise_uncaught_exception(exc)
  File "/Users/zhuzhanhao/opt/anaconda3/envs/py37/lib/python3.7/site-packages/rest_framework/views.py", line 476, in raise_uncaught_exception
    raise exc
  File "/Users/zhuzhanhao/opt/anaconda3/envs/py37/lib/python3.7/site-packages/rest_framework/views.py", line 502, in dispatch
    response = handler(request, *args, **kwargs)
  File "/Users/zhuzhanhao/Easytest/easy/api/Menu/Menu.py", line 31, in get
    main_menu_data = TestSer(obj, many=True).data
  File "/Users/zhuzhanhao/opt/anaconda3/envs/py37/lib/python3.7/site-packages/rest_framework/serializers.py", line 760, in data
    ret = super().data
  File "/Users/zhuzhanhao/opt/anaconda3/envs/py37/lib/python3.7/site-packages/rest_framework/serializers.py", line 260, in data
    self._data = self.to_representation(self.instance)
  File "/Users/zhuzhanhao/opt/anaconda3/envs/py37/lib/python3.7/site-packages/rest_framework/serializers.py", line 678, in to_representation
    self.child.to_representation(item) for item in iterable
  File "/Users/zhuzhanhao/opt/anaconda3/envs/py37/lib/python3.7/site-packages/rest_framework/serializers.py", line 678, in <listcomp>
    self.child.to_representation(item) for item in iterable
  File "/Users/zhuzhanhao/opt/anaconda3/envs/py37/lib/python3.7/site-packages/rest_framework/serializers.py", line 529, in to_representation
    ret[field.field_name] = field.to_representation(attribute)
  File "/Users/zhuzhanhao/opt/anaconda3/envs/py37/lib/python3.7/site-packages/rest_framework/serializers.py", line 514, in to_representation
    for field in fields:
  File "/Users/zhuzhanhao/opt/anaconda3/envs/py37/lib/python3.7/site-packages/rest_framework/serializers.py", line 375, in _readable_fields
    for field in self.fields.values():
  File "/Users/zhuzhanhao/opt/anaconda3/envs/py37/lib/python3.7/site-packages/django/utils/functional.py", line 48, in __get__
    res = instance.__dict__[self.name] = self.func(instance)
  File "/Users/zhuzhanhao/opt/anaconda3/envs/py37/lib/python3.7/site-packages/rest_framework/serializers.py", line 363, in fields
    for key, value in self.get_fields().items():
  File "/Users/zhuzhanhao/opt/anaconda3/envs/py37/lib/python3.7/site-packages/rest_framework/serializers.py", line 1015, in get_fields
    serializer_class=self.__class__.__name__
AssertionError: Class ModelSerializer missing "Meta" attribute
2020-06-12 15:47:29,204,23671,django.server,ERROR,basehttp.py:157,"GET /api/v1/interface_manager/menu/ HTTP/1.1" 500 17990
2020-06-12 15:50:00,856,23775,django.request,ERROR,log.py:228,Internal Server Error: /api/v1/interface_manager/menu/
Traceback (most recent call last):
  File "/Users/zhuzhanhao/opt/anaconda3/envs/py37/lib/python3.7/site-packages/django/core/handlers/exception.py", line 34, in inner
    response = get_response(request)
  File "/Users/zhuzhanhao/opt/anaconda3/envs/py37/lib/python3.7/site-packages/django/core/handlers/base.py", line 115, in _get_response
    response = self.process_exception_by_middleware(e, request)
  File "/Users/zhuzhanhao/opt/anaconda3/envs/py37/lib/python3.7/site-packages/django/core/handlers/base.py", line 113, in _get_response
    response = wrapped_callback(request, *callback_args, **callback_kwargs)
  File "/Users/zhuzhanhao/opt/anaconda3/envs/py37/lib/python3.7/site-packages/django/views/decorators/csrf.py", line 54, in wrapped_view
    return view_func(*args, **kwargs)
  File "/Users/zhuzhanhao/opt/anaconda3/envs/py37/lib/python3.7/site-packages/django/views/generic/base.py", line 71, in view
    return self.dispatch(request, *args, **kwargs)
  File "/Users/zhuzhanhao/opt/anaconda3/envs/py37/lib/python3.7/site-packages/rest_framework/views.py", line 505, in dispatch
    response = self.handle_exception(exc)
  File "/Users/zhuzhanhao/opt/anaconda3/envs/py37/lib/python3.7/site-packages/rest_framework/views.py", line 465, in handle_exception
    self.raise_uncaught_exception(exc)
  File "/Users/zhuzhanhao/opt/anaconda3/envs/py37/lib/python3.7/site-packages/rest_framework/views.py", line 476, in raise_uncaught_exception
    raise exc
  File "/Users/zhuzhanhao/opt/anaconda3/envs/py37/lib/python3.7/site-packages/rest_framework/views.py", line 502, in dispatch
    response = handler(request, *args, **kwargs)
  File "/Users/zhuzhanhao/Easytest/easy/api/Menu/Menu.py", line 31, in get
    main_menu_data = TestSer(obj, many=True).data
  File "/Users/zhuzhanhao/opt/anaconda3/envs/py37/lib/python3.7/site-packages/rest_framework/serializers.py", line 760, in data
    ret = super().data
  File "/Users/zhuzhanhao/opt/anaconda3/envs/py37/lib/python3.7/site-packages/rest_framework/serializers.py", line 260, in data
    self._data = self.to_representation(self.instance)
  File "/Users/zhuzhanhao/opt/anaconda3/envs/py37/lib/python3.7/site-packages/rest_framework/serializers.py", line 678, in to_representation
    self.child.to_representation(item) for item in iterable
  File "/Users/zhuzhanhao/opt/anaconda3/envs/py37/lib/python3.7/site-packages/rest_framework/serializers.py", line 678, in <listcomp>
    self.child.to_representation(item) for item in iterable
  File "/Users/zhuzhanhao/opt/anaconda3/envs/py37/lib/python3.7/site-packages/rest_framework/serializers.py", line 529, in to_representation
    ret[field.field_name] = field.to_representation(attribute)
  File "/Users/zhuzhanhao/opt/anaconda3/envs/py37/lib/python3.7/site-packages/rest_framework/serializers.py", line 514, in to_representation
    for field in fields:
  File "/Users/zhuzhanhao/opt/anaconda3/envs/py37/lib/python3.7/site-packages/rest_framework/serializers.py", line 375, in _readable_fields
    for field in self.fields.values():
  File "/Users/zhuzhanhao/opt/anaconda3/envs/py37/lib/python3.7/site-packages/django/utils/functional.py", line 48, in __get__
    res = instance.__dict__[self.name] = self.func(instance)
  File "/Users/zhuzhanhao/opt/anaconda3/envs/py37/lib/python3.7/site-packages/rest_framework/serializers.py", line 363, in fields
    for key, value in self.get_fields().items():
  File "/Users/zhuzhanhao/opt/anaconda3/envs/py37/lib/python3.7/site-packages/rest_framework/serializers.py", line 1015, in get_fields
    serializer_class=self.__class__.__name__
AssertionError: Class ModelSerializer missing "Meta" attribute
2020-06-12 15:50:00,868,23775,django.server,ERROR,basehttp.py:157,"GET /api/v1/interface_manager/menu/ HTTP/1.1" 500 17990
2020-06-12 22:07:31,676,7784,django.request,ERROR,log.py:228,Internal Server Error: /interface_case/
Traceback (most recent call last):
  File "D:\Anaconda3\envs\test\lib\site-packages\django\db\models\fields\__init__.py", line 1772, in get_prep_value
    return int(value)
ValueError: invalid literal for int() with base 10: ''

The above exception was the direct cause of the following exception:

Traceback (most recent call last):
  File "D:\Anaconda3\envs\test\lib\site-packages\django\core\handlers\exception.py", line 34, in inner
    response = get_response(request)
  File "D:\Anaconda3\envs\test\lib\site-packages\django\core\handlers\base.py", line 115, in _get_response
    response = self.process_exception_by_middleware(e, request)
  File "D:\Anaconda3\envs\test\lib\site-packages\django\core\handlers\base.py", line 113, in _get_response
    response = wrapped_callback(request, *callback_args, **callback_kwargs)
  File "D:\python\project\Easytest\easy\api\renderHtml.py", line 28, in interface_set_views
    puisne_module = InterFaceManageModule.objects.get(id=parentId)
  File "D:\Anaconda3\envs\test\lib\site-packages\django\db\models\manager.py", line 82, in manager_method
    return getattr(self.get_queryset(), name)(*args, **kwargs)
  File "D:\Anaconda3\envs\test\lib\site-packages\django\db\models\query.py", line 404, in get
    clone = self._chain() if self.query.combinator else self.filter(*args, **kwargs)
  File "D:\Anaconda3\envs\test\lib\site-packages\django\db\models\query.py", line 904, in filter
    return self._filter_or_exclude(False, *args, **kwargs)
  File "D:\Anaconda3\envs\test\lib\site-packages\django\db\models\query.py", line 923, in _filter_or_exclude
    clone.query.add_q(Q(*args, **kwargs))
  File "D:\Anaconda3\envs\test\lib\site-packages\django\db\models\sql\query.py", line 1350, in add_q
    clause, _ = self._add_q(q_object, self.used_aliases)
  File "D:\Anaconda3\envs\test\lib\site-packages\django\db\models\sql\query.py", line 1381, in _add_q
    check_filterable=check_filterable,
  File "D:\Anaconda3\envs\test\lib\site-packages\django\db\models\sql\query.py", line 1311, in build_filter
    condition = self.build_lookup(lookups, col, value)
  File "D:\Anaconda3\envs\test\lib\site-packages\django\db\models\sql\query.py", line 1165, in build_lookup
    lookup = lookup_class(lhs, rhs)
  File "D:\Anaconda3\envs\test\lib\site-packages\django\db\models\lookups.py", line 22, in __init__
    self.rhs = self.get_prep_lookup()
  File "D:\Anaconda3\envs\test\lib\site-packages\django\db\models\lookups.py", line 72, in get_prep_lookup
    return self.lhs.output_field.get_prep_value(self.rhs)
  File "D:\Anaconda3\envs\test\lib\site-packages\django\db\models\fields\__init__.py", line 1776, in get_prep_value
    ) from e
ValueError: Field 'id' expected a number but got ''.
2020-06-12 22:07:31,679,7784,django.server,ERROR,basehttp.py:157,"GET /interface_case/ HTTP/1.1" 500 125370
2020-06-12 22:10:10,392,7784,django.request,ERROR,log.py:228,Internal Server Error: /interface_case/
Traceback (most recent call last):
  File "D:\Anaconda3\envs\test\lib\site-packages\django\db\models\fields\__init__.py", line 1772, in get_prep_value
    return int(value)
ValueError: invalid literal for int() with base 10: ''

The above exception was the direct cause of the following exception:

Traceback (most recent call last):
  File "D:\Anaconda3\envs\test\lib\site-packages\django\core\handlers\exception.py", line 34, in inner
    response = get_response(request)
  File "D:\Anaconda3\envs\test\lib\site-packages\django\core\handlers\base.py", line 115, in _get_response
    response = self.process_exception_by_middleware(e, request)
  File "D:\Anaconda3\envs\test\lib\site-packages\django\core\handlers\base.py", line 113, in _get_response
    response = wrapped_callback(request, *callback_args, **callback_kwargs)
  File "D:\python\project\Easytest\easy\api\renderHtml.py", line 28, in interface_set_views
    puisne_module = InterFaceManageModule.objects.get(id=parentId)
  File "D:\Anaconda3\envs\test\lib\site-packages\django\db\models\manager.py", line 82, in manager_method
    return getattr(self.get_queryset(), name)(*args, **kwargs)
  File "D:\Anaconda3\envs\test\lib\site-packages\django\db\models\query.py", line 404, in get
    clone = self._chain() if self.query.combinator else self.filter(*args, **kwargs)
  File "D:\Anaconda3\envs\test\lib\site-packages\django\db\models\query.py", line 904, in filter
    return self._filter_or_exclude(False, *args, **kwargs)
  File "D:\Anaconda3\envs\test\lib\site-packages\django\db\models\query.py", line 923, in _filter_or_exclude
    clone.query.add_q(Q(*args, **kwargs))
  File "D:\Anaconda3\envs\test\lib\site-packages\django\db\models\sql\query.py", line 1350, in add_q
    clause, _ = self._add_q(q_object, self.used_aliases)
  File "D:\Anaconda3\envs\test\lib\site-packages\django\db\models\sql\query.py", line 1381, in _add_q
    check_filterable=check_filterable,
  File "D:\Anaconda3\envs\test\lib\site-packages\django\db\models\sql\query.py", line 1311, in build_filter
    condition = self.build_lookup(lookups, col, value)
  File "D:\Anaconda3\envs\test\lib\site-packages\django\db\models\sql\query.py", line 1165, in build_lookup
    lookup = lookup_class(lhs, rhs)
  File "D:\Anaconda3\envs\test\lib\site-packages\django\db\models\lookups.py", line 22, in __init__
    self.rhs = self.get_prep_lookup()
  File "D:\Anaconda3\envs\test\lib\site-packages\django\db\models\lookups.py", line 72, in get_prep_lookup
    return self.lhs.output_field.get_prep_value(self.rhs)
  File "D:\Anaconda3\envs\test\lib\site-packages\django\db\models\fields\__init__.py", line 1776, in get_prep_value
    ) from e
ValueError: Field 'id' expected a number but got ''.
2020-06-12 22:10:10,393,7784,django.server,ERROR,basehttp.py:157,"GET /interface_case/ HTTP/1.1" 500 125370
2020-06-12 22:38:43,445,10032,django.request,ERROR,log.py:228,Internal Server Error: /api/v1/interface_case/list/
Traceback (most recent call last):
  File "D:\Anaconda3\envs\test\lib\site-packages\django\db\models\fields\__init__.py", line 1772, in get_prep_value
    return int(value)
ValueError: invalid literal for int() with base 10: ''

The above exception was the direct cause of the following exception:

Traceback (most recent call last):
  File "D:\Anaconda3\envs\test\lib\site-packages\django\core\handlers\exception.py", line 34, in inner
    response = get_response(request)
  File "D:\Anaconda3\envs\test\lib\site-packages\django\core\handlers\base.py", line 115, in _get_response
    response = self.process_exception_by_middleware(e, request)
  File "D:\Anaconda3\envs\test\lib\site-packages\django\core\handlers\base.py", line 113, in _get_response
    response = wrapped_callback(request, *callback_args, **callback_kwargs)
  File "D:\Anaconda3\envs\test\lib\site-packages\django\views\decorators\csrf.py", line 54, in wrapped_view
    return view_func(*args, **kwargs)
  File "D:\Anaconda3\envs\test\lib\site-packages\django\views\generic\base.py", line 71, in view
    return self.dispatch(request, *args, **kwargs)
  File "D:\Anaconda3\envs\test\lib\site-packages\rest_framework\views.py", line 505, in dispatch
    response = self.handle_exception(exc)
  File "D:\Anaconda3\envs\test\lib\site-packages\rest_framework\views.py", line 465, in handle_exception
    self.raise_uncaught_exception(exc)
  File "D:\Anaconda3\envs\test\lib\site-packages\rest_framework\views.py", line 476, in raise_uncaught_exception
    raise exc
  File "D:\Anaconda3\envs\test\lib\site-packages\rest_framework\views.py", line 502, in dispatch
    response = handler(request, *args, **kwargs)
  File "D:\python\project\Easytest\easy\api\interFace\interfaceManage.py", line 143, in get
    obj = InterFaceSet.objects.filter(belong_module=parentId)
  File "D:\Anaconda3\envs\test\lib\site-packages\django\db\models\manager.py", line 82, in manager_method
    return getattr(self.get_queryset(), name)(*args, **kwargs)
  File "D:\Anaconda3\envs\test\lib\site-packages\django\db\models\query.py", line 904, in filter
    return self._filter_or_exclude(False, *args, **kwargs)
  File "D:\Anaconda3\envs\test\lib\site-packages\django\db\models\query.py", line 923, in _filter_or_exclude
    clone.query.add_q(Q(*args, **kwargs))
  File "D:\Anaconda3\envs\test\lib\site-packages\django\db\models\sql\query.py", line 1350, in add_q
    clause, _ = self._add_q(q_object, self.used_aliases)
  File "D:\Anaconda3\envs\test\lib\site-packages\django\db\models\sql\query.py", line 1381, in _add_q
    check_filterable=check_filterable,
  File "D:\Anaconda3\envs\test\lib\site-packages\django\db\models\sql\query.py", line 1311, in build_filter
    condition = self.build_lookup(lookups, col, value)
  File "D:\Anaconda3\envs\test\lib\site-packages\django\db\models\sql\query.py", line 1165, in build_lookup
    lookup = lookup_class(lhs, rhs)
  File "D:\Anaconda3\envs\test\lib\site-packages\django\db\models\lookups.py", line 22, in __init__
    self.rhs = self.get_prep_lookup()
  File "D:\Anaconda3\envs\test\lib\site-packages\django\db\models\fields\related_lookups.py", line 115, in get_prep_lookup
    self.rhs = target_field.get_prep_value(self.rhs)
  File "D:\Anaconda3\envs\test\lib\site-packages\django\db\models\fields\__init__.py", line 1776, in get_prep_value
    ) from e
ValueError: Field 'id' expected a number but got ''.
2020-06-12 22:38:43,448,10032,django.server,ERROR,basehttp.py:157,"GET /api/v1/interface_case/list/?page=1&limit=10&parentId= HTTP/1.1" 500 18851
2020-06-12 22:52:10,927,10032,django.request,ERROR,log.py:228,Internal Server Error: /api/v1/interface_case/list/
Traceback (most recent call last):
  File "D:\Anaconda3\envs\test\lib\site-packages\django\db\models\fields\__init__.py", line 1772, in get_prep_value
    return int(value)
ValueError: invalid literal for int() with base 10: ''

The above exception was the direct cause of the following exception:

Traceback (most recent call last):
  File "D:\Anaconda3\envs\test\lib\site-packages\django\core\handlers\exception.py", line 34, in inner
    response = get_response(request)
  File "D:\Anaconda3\envs\test\lib\site-packages\django\core\handlers\base.py", line 115, in _get_response
    response = self.process_exception_by_middleware(e, request)
  File "D:\Anaconda3\envs\test\lib\site-packages\django\core\handlers\base.py", line 113, in _get_response
    response = wrapped_callback(request, *callback_args, **callback_kwargs)
  File "D:\Anaconda3\envs\test\lib\site-packages\django\views\decorators\csrf.py", line 54, in wrapped_view
    return view_func(*args, **kwargs)
  File "D:\Anaconda3\envs\test\lib\site-packages\django\views\generic\base.py", line 71, in view
    return self.dispatch(request, *args, **kwargs)
  File "D:\Anaconda3\envs\test\lib\site-packages\rest_framework\views.py", line 505, in dispatch
    response = self.handle_exception(exc)
  File "D:\Anaconda3\envs\test\lib\site-packages\rest_framework\views.py", line 465, in handle_exception
    self.raise_uncaught_exception(exc)
  File "D:\Anaconda3\envs\test\lib\site-packages\rest_framework\views.py", line 476, in raise_uncaught_exception
    raise exc
  File "D:\Anaconda3\envs\test\lib\site-packages\rest_framework\views.py", line 502, in dispatch
    response = handler(request, *args, **kwargs)
  File "D:\python\project\Easytest\easy\api\interFace\interfaceManage.py", line 143, in get
    obj = InterFaceSet.objects.filter(belong_module=parentId)
  File "D:\Anaconda3\envs\test\lib\site-packages\django\db\models\manager.py", line 82, in manager_method
    return getattr(self.get_queryset(), name)(*args, **kwargs)
  File "D:\Anaconda3\envs\test\lib\site-packages\django\db\models\query.py", line 904, in filter
    return self._filter_or_exclude(False, *args, **kwargs)
  File "D:\Anaconda3\envs\test\lib\site-packages\django\db\models\query.py", line 923, in _filter_or_exclude
    clone.query.add_q(Q(*args, **kwargs))
  File "D:\Anaconda3\envs\test\lib\site-packages\django\db\models\sql\query.py", line 1350, in add_q
    clause, _ = self._add_q(q_object, self.used_aliases)
  File "D:\Anaconda3\envs\test\lib\site-packages\django\db\models\sql\query.py", line 1381, in _add_q
    check_filterable=check_filterable,
  File "D:\Anaconda3\envs\test\lib\site-packages\django\db\models\sql\query.py", line 1311, in build_filter
    condition = self.build_lookup(lookups, col, value)
  File "D:\Anaconda3\envs\test\lib\site-packages\django\db\models\sql\query.py", line 1165, in build_lookup
    lookup = lookup_class(lhs, rhs)
  File "D:\Anaconda3\envs\test\lib\site-packages\django\db\models\lookups.py", line 22, in __init__
    self.rhs = self.get_prep_lookup()
  File "D:\Anaconda3\envs\test\lib\site-packages\django\db\models\fields\related_lookups.py", line 115, in get_prep_lookup
    self.rhs = target_field.get_prep_value(self.rhs)
  File "D:\Anaconda3\envs\test\lib\site-packages\django\db\models\fields\__init__.py", line 1776, in get_prep_value
    ) from e
ValueError: Field 'id' expected a number but got ''.
2020-06-12 22:52:10,928,10032,django.server,ERROR,basehttp.py:157,"GET /api/v1/interface_case/list/?page=1&limit=10&parentId= HTTP/1.1" 500 18851
2020-06-12 23:03:42,469,10032,django.request,ERROR,log.py:228,Internal Server Error: /api/v1/interface_case/list/
Traceback (most recent call last):
  File "D:\Anaconda3\envs\test\lib\site-packages\django\db\models\fields\__init__.py", line 1772, in get_prep_value
    return int(value)
ValueError: invalid literal for int() with base 10: ''

The above exception was the direct cause of the following exception:

Traceback (most recent call last):
  File "D:\Anaconda3\envs\test\lib\site-packages\django\core\handlers\exception.py", line 34, in inner
    response = get_response(request)
  File "D:\Anaconda3\envs\test\lib\site-packages\django\core\handlers\base.py", line 115, in _get_response
    response = self.process_exception_by_middleware(e, request)
  File "D:\Anaconda3\envs\test\lib\site-packages\django\core\handlers\base.py", line 113, in _get_response
    response = wrapped_callback(request, *callback_args, **callback_kwargs)
  File "D:\Anaconda3\envs\test\lib\site-packages\django\views\decorators\csrf.py", line 54, in wrapped_view
    return view_func(*args, **kwargs)
  File "D:\Anaconda3\envs\test\lib\site-packages\django\views\generic\base.py", line 71, in view
    return self.dispatch(request, *args, **kwargs)
  File "D:\Anaconda3\envs\test\lib\site-packages\rest_framework\views.py", line 505, in dispatch
    response = self.handle_exception(exc)
  File "D:\Anaconda3\envs\test\lib\site-packages\rest_framework\views.py", line 465, in handle_exception
    self.raise_uncaught_exception(exc)
  File "D:\Anaconda3\envs\test\lib\site-packages\rest_framework\views.py", line 476, in raise_uncaught_exception
    raise exc
  File "D:\Anaconda3\envs\test\lib\site-packages\rest_framework\views.py", line 502, in dispatch
    response = handler(request, *args, **kwargs)
  File "D:\python\project\Easytest\easy\api\interFace\interfaceManage.py", line 143, in get
    obj = InterFaceSet.objects.filter(belong_module=parentId)
  File "D:\Anaconda3\envs\test\lib\site-packages\django\db\models\manager.py", line 82, in manager_method
    return getattr(self.get_queryset(), name)(*args, **kwargs)
  File "D:\Anaconda3\envs\test\lib\site-packages\django\db\models\query.py", line 904, in filter
    return self._filter_or_exclude(False, *args, **kwargs)
  File "D:\Anaconda3\envs\test\lib\site-packages\django\db\models\query.py", line 923, in _filter_or_exclude
    clone.query.add_q(Q(*args, **kwargs))
  File "D:\Anaconda3\envs\test\lib\site-packages\django\db\models\sql\query.py", line 1350, in add_q
    clause, _ = self._add_q(q_object, self.used_aliases)
  File "D:\Anaconda3\envs\test\lib\site-packages\django\db\models\sql\query.py", line 1381, in _add_q
    check_filterable=check_filterable,
  File "D:\Anaconda3\envs\test\lib\site-packages\django\db\models\sql\query.py", line 1311, in build_filter
    condition = self.build_lookup(lookups, col, value)
  File "D:\Anaconda3\envs\test\lib\site-packages\django\db\models\sql\query.py", line 1165, in build_lookup
    lookup = lookup_class(lhs, rhs)
  File "D:\Anaconda3\envs\test\lib\site-packages\django\db\models\lookups.py", line 22, in __init__
    self.rhs = self.get_prep_lookup()
  File "D:\Anaconda3\envs\test\lib\site-packages\django\db\models\fields\related_lookups.py", line 115, in get_prep_lookup
    self.rhs = target_field.get_prep_value(self.rhs)
  File "D:\Anaconda3\envs\test\lib\site-packages\django\db\models\fields\__init__.py", line 1776, in get_prep_value
    ) from e
ValueError: Field 'id' expected a number but got ''.
2020-06-12 23:03:42,470,10032,django.server,ERROR,basehttp.py:157,"GET /api/v1/interface_case/list/?page=1&limit=10&parentId= HTTP/1.1" 500 18851
2020-06-12 23:10:38,769,10032,django.request,ERROR,log.py:228,Internal Server Error: /api/v1/interface_case/list/
Traceback (most recent call last):
  File "D:\Anaconda3\envs\test\lib\site-packages\django\db\models\fields\__init__.py", line 1772, in get_prep_value
    return int(value)
ValueError: invalid literal for int() with base 10: ''

The above exception was the direct cause of the following exception:

Traceback (most recent call last):
  File "D:\Anaconda3\envs\test\lib\site-packages\django\core\handlers\exception.py", line 34, in inner
    response = get_response(request)
  File "D:\Anaconda3\envs\test\lib\site-packages\django\core\handlers\base.py", line 115, in _get_response
    response = self.process_exception_by_middleware(e, request)
  File "D:\Anaconda3\envs\test\lib\site-packages\django\core\handlers\base.py", line 113, in _get_response
    response = wrapped_callback(request, *callback_args, **callback_kwargs)
  File "D:\Anaconda3\envs\test\lib\site-packages\django\views\decorators\csrf.py", line 54, in wrapped_view
    return view_func(*args, **kwargs)
  File "D:\Anaconda3\envs\test\lib\site-packages\django\views\generic\base.py", line 71, in view
    return self.dispatch(request, *args, **kwargs)
  File "D:\Anaconda3\envs\test\lib\site-packages\rest_framework\views.py", line 505, in dispatch
    response = self.handle_exception(exc)
  File "D:\Anaconda3\envs\test\lib\site-packages\rest_framework\views.py", line 465, in handle_exception
    self.raise_uncaught_exception(exc)
  File "D:\Anaconda3\envs\test\lib\site-packages\rest_framework\views.py", line 476, in raise_uncaught_exception
    raise exc
  File "D:\Anaconda3\envs\test\lib\site-packages\rest_framework\views.py", line 502, in dispatch
    response = handler(request, *args, **kwargs)
  File "D:\python\project\Easytest\easy\api\interFace\interfaceManage.py", line 143, in get
    obj = InterFaceSet.objects.filter(belong_module=parentId)
  File "D:\Anaconda3\envs\test\lib\site-packages\django\db\models\manager.py", line 82, in manager_method
    return getattr(self.get_queryset(), name)(*args, **kwargs)
  File "D:\Anaconda3\envs\test\lib\site-packages\django\db\models\query.py", line 904, in filter
    return self._filter_or_exclude(False, *args, **kwargs)
  File "D:\Anaconda3\envs\test\lib\site-packages\django\db\models\query.py", line 923, in _filter_or_exclude
    clone.query.add_q(Q(*args, **kwargs))
  File "D:\Anaconda3\envs\test\lib\site-packages\django\db\models\sql\query.py", line 1350, in add_q
    clause, _ = self._add_q(q_object, self.used_aliases)
  File "D:\Anaconda3\envs\test\lib\site-packages\django\db\models\sql\query.py", line 1381, in _add_q
    check_filterable=check_filterable,
  File "D:\Anaconda3\envs\test\lib\site-packages\django\db\models\sql\query.py", line 1311, in build_filter
    condition = self.build_lookup(lookups, col, value)
  File "D:\Anaconda3\envs\test\lib\site-packages\django\db\models\sql\query.py", line 1165, in build_lookup
    lookup = lookup_class(lhs, rhs)
  File "D:\Anaconda3\envs\test\lib\site-packages\django\db\models\lookups.py", line 22, in __init__
    self.rhs = self.get_prep_lookup()
  File "D:\Anaconda3\envs\test\lib\site-packages\django\db\models\fields\related_lookups.py", line 115, in get_prep_lookup
    self.rhs = target_field.get_prep_value(self.rhs)
  File "D:\Anaconda3\envs\test\lib\site-packages\django\db\models\fields\__init__.py", line 1776, in get_prep_value
    ) from e
ValueError: Field 'id' expected a number but got ''.
2020-06-12 23:10:38,770,10032,django.server,ERROR,basehttp.py:157,"GET /api/v1/interface_case/list/?page=1&limit=10&parentId= HTTP/1.1" 500 18851
